<?xml version="1.0" encoding="utf-8"?>
<!-- This URDF was automatically created by SolidWorks to URDF Exporter! Originally created by Stephen Brawner (brawner@gmail.com) 
     Commit Version: 1.6.0-4-g7f85cfe  Build Version: 1.6.7995.38578
     For more information, please see http://wiki.ros.org/sw_urdf_exporter -->
<robot
  name="GrasperAndGantry">
  <link
    name="base_link">
    <inertial>
      <origin
        xyz="-1.719E-16 -0.041985 0.017902"
        rpy="0 0 0" />
      <mass
        value="5.7776" />
      <inertia
        ixx="0.32319"
        ixy="1.4897E-16"
        ixz="3.4335E-19"
        iyy="0.27326"
        iyz="1.3637E-17"
        izz="0.59578" />
    </inertial>
    <visual>
      <origin
        xyz="0 0 0"
        rpy="0 0 0" />
      <geometry>
        <mesh
          filename="package://GrasperAndGantry/meshes/base_link.STL" />
      </geometry>
      <material
        name="">
        <color
          rgba="0.89804 0.91765 0.92941 1" />
      </material>
    </visual>
    <collision>
      <origin
        xyz="0 0 0"
        rpy="0 0 0" />
      <geometry>
        <mesh
          filename="package://GrasperAndGantry/meshes/base_link.STL" />
      </geometry>
    </collision>
  </link>
  <link
    name="LeftUpright">
    <inertial>
      <origin
        xyz="-0.28158 0.35631 -0.041985"
        rpy="0 0 0" />
      <mass
        value="1.4886" />
      <inertia
        ixx="0.056019"
        ixy="1.7816E-18"
        ixz="1.5056E-19"
        iyy="0.00025146"
        iyz="2.4679E-19"
        izz="0.056166" />
    </inertial>
    <visual>
      <origin
        xyz="0 0 0"
        rpy="0 0 0" />
      <geometry>
        <mesh
          filename="package://GrasperAndGantry/meshes/LeftUpright.STL" />
      </geometry>
      <material
        name="">
        <color
          rgba="0.89804 0.91765 0.92941 1" />
      </material>
    </visual>
    <collision>
      <origin
        xyz="0 0 0"
        rpy="0 0 0" />
      <geometry>
        <mesh
          filename="package://GrasperAndGantry/meshes/LeftUpright.STL" />
      </geometry>
    </collision>
  </link>
  <joint
    name="LeftUprightJoint"
    type="fixed">
    <origin
      xyz="0 -0.041985 0"
      rpy="1.5708 0 0" />
    <parent
      link="base_link" />
    <child
      link="LeftUpright" />
    <axis
      xyz="0 0 0" />
  </joint>
  <link
    name="ZBar">
    <inertial>
      <origin
        xyz="2.2859E-15 0.010235 -0.041985"
        rpy="0 0 0" />
      <mass
        value="0.92261" />
      <inertia
        ixx="0.00010656"
        ixy="-4.2485E-20"
        ixz="3.0107E-18"
        iyy="0.023961"
        iyz="2.4839E-21"
        izz="0.023919" />
    </inertial>
    <visual>
      <origin
        xyz="0 0 0"
        rpy="0 0 0" />
      <geometry>
        <mesh
          filename="package://GrasperAndGantry/meshes/ZBar.STL" />
      </geometry>
      <material
        name="">
        <color
          rgba="0.89412 0.91373 0.92941 1" />
      </material>
    </visual>
    <collision>
      <origin
        xyz="0 0 0"
        rpy="0 0 0" />
      <geometry>
        <mesh
          filename="package://GrasperAndGantry/meshes/ZBar.STL" />
      </geometry>
    </collision>
  </link>
  <joint
    name="ZBar_Joint"
    type="prismatic">
    <origin
      xyz="0 0.56296 0"
      rpy="0 0 0" />
    <parent
      link="LeftUpright" />
    <child
      link="ZBar" />
    <axis
      xyz="0 1 0" />
    <limit
      lower="-0.5"
      upper="0"
      effort="0"
      velocity="0" />
  </joint>
  <link
    name="GrasperBase">
    <inertial>
      <origin
        xyz="-0.028605 0.017479 3.8734E-16"
        rpy="0 0 0" />
      <mass
        value="0.26347" />
      <inertia
        ixx="8.1922E-05"
        ixy="-3.9184E-22"
        ixz="-1.6378E-21"
        iyy="0.00012733"
        iyz="1.3026E-21"
        izz="9.9473E-05" />
    </inertial>
    <visual>
      <origin
        xyz="0 0 0"
        rpy="0 0 0" />
      <geometry>
        <mesh
          filename="package://GrasperAndGantry/meshes/GrasperBase.STL" />
      </geometry>
      <material
        name="">
        <color
          rgba="0.89412 0.91373 0.92941 1" />
      </material>
    </visual>
    <collision>
      <origin
        xyz="0 0 0"
        rpy="0 0 0" />
      <geometry>
        <mesh
          filename="package://GrasperAndGantry/meshes/GrasperBase.STL" />
      </geometry>
    </collision>
  </link>
  <joint
    name="GrasperBase"
    type="prismatic">
    <origin
      xyz="0.028605 -0.0348 -0.041985"
      rpy="0 0 0" />
    <parent
      link="ZBar" />
    <child
      link="GrasperBase" />
    <axis
      xyz="1 0 0" />
    <limit
      lower="-0.2"
      upper="0.2"
      effort="0"
      velocity="0" />
  </joint>
  <link
    name="GrasperConnector">
    <inertial>
      <origin
        xyz="1.5935E-17 0.090818 1.2891E-15"
        rpy="0 0 0" />
      <mass
        value="0.092827" />
      <inertia
        ixx="0.00014637"
        ixy="1.0134E-18"
        ixz="-4.9036E-19"
        iyy="0.00027935"
        iyz="3.4682E-18"
        izz="0.00014637" />
    </inertial>
    <visual>
      <origin
        xyz="0 0 0"
        rpy="0 0 0" />
      <geometry>
        <mesh
          filename="package://GrasperAndGantry/meshes/GrasperConnector.STL" />
      </geometry>
      <material
        name="">
        <color
          rgba="0.79216 0.81961 0.93333 1" />
      </material>
    </visual>
    <collision>
      <origin
        xyz="0 0 0"
        rpy="0 0 0" />
      <geometry>
        <mesh
          filename="package://GrasperAndGantry/meshes/GrasperConnector.STL" />
      </geometry>
    </collision>
  </link>
  <joint
    name="GBGB"
    type="fixed">
    <origin
      xyz="-0.028605 -0.10472 0"
      rpy="0 0 0" />
    <parent
      link="GrasperBase" />
    <child
      link="GrasperConnector" />
    <axis
      xyz="0 0 0" />
  </joint>
  <link
    name="CylinderCons">
    <inertial>
      <origin
        xyz="-3.16E-15 0.0028145 2.5434E-15"
        rpy="0 0 0" />
      <mass
        value="0.0026009" />
      <inertia
        ixx="7.883E-06"
        ixy="1.4399E-21"
        ixz="-5.4643E-21"
        iyy="1.5503E-05"
        iyz="1.3506E-20"
        izz="7.883E-06" />
    </inertial>
    <visual>
      <origin
        xyz="0 0 0"
        rpy="0 0 0" />
      <geometry>
        <mesh
          filename="package://GrasperAndGantry/meshes/CylinderCons.STL" />
      </geometry>
      <material
        name="">
        <color
          rgba="0.79216 0.81961 0.93333 1" />
      </material>
    </visual>
    <collision>
      <origin
        xyz="0 0 0"
        rpy="0 0 0" />
      <geometry>
        <mesh
          filename="package://GrasperAndGantry/meshes/CylinderCons.STL" />
      </geometry>
    </collision>
  </link>
  <joint
    name="BCC"
    type="fixed">
    <origin
      xyz="0 0 0"
      rpy="0 0 0" />
    <parent
      link="GrasperConnector" />
    <child
      link="CylinderCons" />
    <axis
      xyz="0 0 0" />
  </joint>
  <link
    name="SoftSupport1">
    <inertial>
      <origin
        xyz="-3.4907E-15 -6.088E-05 -0.069509"
        rpy="0 0 0" />
      <mass
        value="0.020019" />
      <inertia
        ixx="2.8922E-06"
        ixy="1.8558E-21"
        ixz="1.5663E-20"
        iyy="3.6958E-06"
        iyz="-8.3292E-10"
        izz="5.9269E-06" />
    </inertial>
    <visual>
      <origin
        xyz="0 0 0"
        rpy="0 0 0" />
      <geometry>
        <mesh
          filename="package://GrasperAndGantry/meshes/SoftSupport1.STL" />
      </geometry>
      <material
        name="">
        <color
          rgba="0.79216 0.81961 0.93333 1" />
      </material>
    </visual>
    <collision>
      <origin
        xyz="0 0 0"
        rpy="0 0 0" />
      <geometry>
        <mesh
          filename="package://GrasperAndGantry/meshes/SoftSupport1.STL" />
      </geometry>
    </collision>
  </link>
  <joint
    name="LinearJaw1"
    type="prismatic">
    <origin
      xyz="0 0 0"
      rpy="0 0 0" />
    <parent
      link="CylinderCons" />
    <child
      link="SoftSupport1" />
    <axis
      xyz="0 0 1" />
    <limit
      lower="0"
      upper="1"
      effort="0"
      velocity="0" />
    <dynamics
      damping="0.1"
      friction="0.1" />
  </joint>
  <link
    name="SoftJaw1">
    <inertial>
      <origin
        xyz="-3.4944E-15 0 -0.054391"
        rpy="0 0 0" />
      <mass
        value="0.015121" />
      <inertia
        ixx="1.7236E-06"
        ixy="-4.3817E-21"
        ixz="-2.0706E-21"
        iyy="1.331E-06"
        iyz="-4.0882E-22"
        izz="2.4259E-06" />
    </inertial>
    <visual>
      <origin
        xyz="0 0 0"
        rpy="0 0 0" />
      <geometry>
        <mesh
          filename="package://GrasperAndGantry/meshes/SoftJaw1.STL" />
      </geometry>
      <material
        name="">
        <color
          rgba="0.79216 0.81961 0.93333 1" />
      </material>
    </visual>
    <collision>
      <origin
        xyz="0 0 0"
        rpy="0 0 0" />
      <geometry>
        <mesh
          filename="package://GrasperAndGantry/meshes/SoftJaw1.STL" />
      </geometry>
    </collision>
  </link>
  <joint
    name="SJ1"
    type="fixed">
    <origin
      xyz="0 0 0"
      rpy="0 0 0" />
    <parent
      link="SoftSupport1" />
    <child
      link="SoftJaw1" />
    <axis
      xyz="0 0 0" />
  </joint>
  <link
    name="SoftSupport2">
    <inertial>
      <origin
        xyz="5.0259E-09 -6.0879E-05 -0.069509"
        rpy="0 0 0" />
      <mass
        value="0.020019" />
      <inertia
        ixx="2.8922E-06"
        ixy="-2.1735E-13"
        ixz="-2.0391E-13"
        iyy="3.6958E-06"
        iyz="-8.3305E-10"
        izz="5.9269E-06" />
    </inertial>
    <visual>
      <origin
        xyz="0 0 0"
        rpy="0 0 0" />
      <geometry>
        <mesh
          filename="package://GrasperAndGantry/meshes/SoftSupport2.STL" />
      </geometry>
      <material
        name="">
        <color
          rgba="0.79216 0.81961 0.93333 1" />
      </material>
    </visual>
    <collision>
      <origin
        xyz="0 0 0"
        rpy="0 0 0" />
      <geometry>
        <mesh
          filename="package://GrasperAndGantry/meshes/SoftSupport2.STL" />
      </geometry>
    </collision>
  </link>
  <joint
    name="LinearJaw2"
    type="prismatic">
    <origin
      xyz="0 0 0"
      rpy="3.1416 -1.0472 3.1416" />
    <parent
      link="CylinderCons" />
    <child
      link="SoftSupport2" />
    <axis
      xyz="-0.86603 0 -0.5" />
    <limit
      lower="0"
      upper="1"
      effort="0"
      velocity="0" />
    <dynamics
      damping="0.1"
      friction="0.1" />
  </joint>
  <link
    name="SoftJaw2">
    <inertial>
      <origin
        xyz="-6.7381E-11 5.5511E-17 -0.054391"
        rpy="0 0 0" />
      <mass
        value="0.015121" />
      <inertia
        ixx="1.7236E-06"
        ixy="-1.7784E-21"
        ixz="1.0243E-14"
        iyy="1.331E-06"
        iyz="8.3805E-23"
        izz="2.4259E-06" />
    </inertial>
    <visual>
      <origin
        xyz="0 0 0"
        rpy="0 0 0" />
      <geometry>
        <mesh
          filename="package://GrasperAndGantry/meshes/SoftJaw2.STL" />
      </geometry>
      <material
        name="">
        <color
          rgba="0.79216 0.81961 0.93333 1" />
      </material>
    </visual>
    <collision>
      <origin
        xyz="0 0 0"
        rpy="0 0 0" />
      <geometry>
        <mesh
          filename="package://GrasperAndGantry/meshes/SoftJaw2.STL" />
      </geometry>
    </collision>
  </link>
  <joint
    name="SJ2"
    type="fixed">
    <origin
      xyz="0 0 0"
      rpy="0 0 0" />
    <parent
      link="SoftSupport2" />
    <child
      link="SoftJaw2" />
    <axis
      xyz="0 0 0" />
  </joint>
  <link
    name="SoftSupport3">
    <inertial>
      <origin
        xyz="-5.0259E-09 -6.0879E-05 -0.069509"
        rpy="0 0 0" />
      <mass
        value="0.020019" />
      <inertia
        ixx="2.8922E-06"
        ixy="2.1735E-13"
        ixz="2.0391E-13"
        iyy="3.6958E-06"
        iyz="-8.3305E-10"
        izz="5.9269E-06" />
    </inertial>
    <visual>
      <origin
        xyz="0 0 0"
        rpy="0 0 0" />
      <geometry>
        <mesh
          filename="package://GrasperAndGantry/meshes/SoftSupport3.STL" />
      </geometry>
      <material
        name="">
        <color
          rgba="0.79216 0.81961 0.93333 1" />
      </material>
    </visual>
    <collision>
      <origin
        xyz="0 0 0"
        rpy="0 0 0" />
      <geometry>
        <mesh
          filename="package://GrasperAndGantry/meshes/SoftSupport3.STL" />
      </geometry>
    </collision>
  </link>
  <joint
    name="LinearJaw3"
    type="prismatic">
    <origin
      xyz="0 0 0"
      rpy="3.1416 1.0472 3.1416" />
    <parent
      link="CylinderCons" />
    <child
      link="SoftSupport3" />
    <axis
      xyz="0.86603 0 -0.5" />
    <limit
      lower="0"
      upper="1"
      effort="0"
      velocity="0" />
    <dynamics
      damping="0.1"
      friction="0.1" />
  </joint>
  <link
    name="SoftJaw3">
    <inertial>
      <origin
        xyz="6.7374E-11 5.5511E-17 -0.054391"
        rpy="0 0 0" />
      <mass
        value="0.015121" />
      <inertia
        ixx="1.7236E-06"
        ixy="-2.8035E-21"
        ixz="-1.0243E-14"
        iyy="1.331E-06"
        iyz="-1.2094E-22"
        izz="2.4259E-06" />
    </inertial>
    <visual>
      <origin
        xyz="0 0 0"
        rpy="0 0 0" />
      <geometry>
        <mesh
          filename="package://GrasperAndGantry/meshes/SoftJaw3.STL" />
      </geometry>
      <material
        name="">
        <color
          rgba="0.79216 0.81961 0.93333 1" />
      </material>
    </visual>
    <collision>
      <origin
        xyz="0 0 0"
        rpy="0 0 0" />
      <geometry>
        <mesh
          filename="package://GrasperAndGantry/meshes/SoftJaw3.STL" />
      </geometry>
    </collision>
  </link>
  <joint
    name="SJ3"
    type="fixed">
    <origin
      xyz="0 0 0"
      rpy="0 0 0" />
    <parent
      link="SoftSupport3" />
    <child
      link="SoftJaw3" />
    <axis
      xyz="0 0 0" />
  </joint>
  <link
    name="RightUpright">
    <inertial>
      <origin
        xyz="0.28158 0.35631 -0.041985"
        rpy="0 0 0" />
      <mass
        value="1.4886" />
      <inertia
        ixx="0.056019"
        ixy="1.2421E-18"
        ixz="-2.2308E-19"
        iyy="0.00025146"
        iyz="1.1323E-18"
        izz="0.056166" />
    </inertial>
    <visual>
      <origin
        xyz="0 0 0"
        rpy="0 0 0" />
      <geometry>
        <mesh
          filename="package://GrasperAndGantry/meshes/RightUpright.STL" />
      </geometry>
      <material
        name="">
        <color
          rgba="0.89804 0.91765 0.92941 1" />
      </material>
    </visual>
    <collision>
      <origin
        xyz="0 0 0"
        rpy="0 0 0" />
      <geometry>
        <mesh
          filename="package://GrasperAndGantry/meshes/RightUpright.STL" />
      </geometry>
    </collision>
  </link>
  <joint
    name="RightUprightJoint"
    type="fixed">
    <origin
      xyz="0 -0.041985 0"
      rpy="1.5708 0 0" />
    <parent
      link="base_link" />
    <child
      link="RightUpright" />
    <axis
      xyz="0 0 0" />
    <limit
      lower="-0.5"
      upper="0.5"
      effort="0"
      velocity="0" />
    <dynamics
      damping="0"
      friction="0" />
  </joint>
  <link
    name="BasePlate">
    <inertial>
      <origin
        xyz="0 0 0"
        rpy="0 0 0" />
      <mass
        value="0" />
      <inertia
        ixx="0"
        ixy="0"
        ixz="0"
        iyy="0"
        iyz="0"
        izz="0" />
    </inertial>
    <visual>
      <origin
        xyz="0 0 0"
        rpy="0 0 0" />
      <geometry>
        <mesh
          filename="package://GrasperAndGantry/meshes/BasePlate.STL" />
      </geometry>
      <material
        name="">
        <color
          rgba="1 1 1 1" />
      </material>
    </visual>
    <collision>
      <origin
        xyz="0 0 0"
        rpy="0 0 0" />
      <geometry>
        <mesh
          filename="package://GrasperAndGantry/meshes/BasePlate.STL" />
      </geometry>
    </collision>
  </link>
  <joint
    name="BasePlateJoint"
    type="prismatic">
    <origin
      xyz="0 -0.25718 0.05914"
      rpy="1.5708 0 0" />
    <parent
      link="base_link" />
    <child
      link="BasePlate" />
    <axis
      xyz="0 0 1" />
    <limit
      lower="-0.3"
      upper="0.3"
      effort="0"
      velocity="0" />
    <dynamics
      damping="0"
      friction="3" />
  </joint>
  <link
    name="ObjectBase">
    <inertial>
      <origin
        xyz="2.3079E-50 0.01 3.0679E-19"
        rpy="0 0 0" />
      <mass
        value="0.03817" />
      <inertia
        ixx="3.4194E-06"
        ixy="-1.1064E-38"
        ixz="5.1616E-54"
        iyy="4.2942E-06"
        iyz="-3.4866E-39"
        izz="3.4194E-06" />
    </inertial>
    <visual>
      <origin
        xyz="0 0 0"
        rpy="0 0 0" />
      <geometry>
        <mesh
          filename="package://GrasperAndGantry/meshes/ObjectBase.STL" />
      </geometry>
      <material
        name="">
        <color
          rgba="0.89804 0.91765 0.92941 1" />
      </material>
    </visual>
    <collision>
      <origin
        xyz="0 0 0"
        rpy="0 0 0" />
      <geometry>
        <mesh
          filename="package://GrasperAndGantry/meshes/ObjectBase.STL" />
      </geometry>
    </collision>
  </link>
  <joint
    name="ObjectBaseJoint"
    type="fixed">
    <origin
      xyz="0 0.00382 -0.25718"
      rpy="0 0 0" />
    <parent
      link="BasePlate" />
    <child
      link="ObjectBase" />
    <axis
      xyz="0 0 0" />
  </joint>
</robot>